<?xml version="1.0" encoding="UTF-8"?><testsuite name="nosetests" tests="2" errors="1" failures="0" skip="1"><testcase classname="stateless_tests.stl_general_test.STLBasic_Test" name="test_connectivity" time="15.210"><error type="exceptions.Exception" message="Test failed. Reasons:&#10;Client could not connect"><![CDATA[Traceback (most recent call last):
  File "/sw/packages/python/2.7.4/lib/python2.7/unittest/case.py", line 361, in run
    self.tearDown()
  File "/auto/srg-sce-swinfra-usr/emb/users/hhaim/work/depot/asr1k/emb/private/hhaim/bp_sim_git/trex-core/scripts/automation/regression/stateful_tests/trex_general_test.py", line 507, in tearDown
    raise Exception('Test failed. Reasons:\n%s' % '\n'.join(self.fail_reasons))
Exception: Test failed. Reasons:
Client could not connect
]]></error><system-out><![CDATA[
Starting TRex... done. (0s)
Started TRex
Connecting..........
Error connecting: ?[1m*** [RPC] - Failed to get server response from tcp://10.56.192.189:4501?[22m
Error: Client could not connect
]]></system-out></testcase><testcase classname="stateless_tests.stl_client_test.STLClient_Test" name="test_random_dynamic_add_remove" time="0.001"><skipped type="unittest.case.SkipTest" message="Client could not connect"><![CDATA[SkipTest: Client could not connect
]]></skipped><system-out><![CDATA[Skip: Client could not connect
]]></system-out></testcase></testsuite>